<?xml version="1.0" ?>
<!-- =================================================================================== -->
<!-- |    This document was autogenerated by xacro from mmrobot.xacro                  | -->
<!-- |    EDITING THIS FILE BY HAND IS NOT RECOMMENDED                                 | -->
<!-- =================================================================================== -->
<robot name="mmrobot">
    <material name="silver">
        <color rgba="0.700 0.700 0.700 1.000" />
    </material>
    <transmission name="rear_left_str_tran">
        <type>transmission_interface/SimpleTransmission</type>
        <joint name="rear_left_str">
            <hardwareInterface>hardware_interface/EffortJointInterface</hardwareInterface>
        </joint>
        <actuator name="rear_left_str_actr">
            <hardwareInterface>hardware_interface/EffortJointInterface</hardwareInterface>
            <mechanicalReduction>1</mechanicalReduction>
        </actuator>
    </transmission>
    <transmission name="front_left_str_tran">
        <type>transmission_interface/SimpleTransmission</type>
        <joint name="front_left_str">
            <hardwareInterface>hardware_interface/EffortJointInterface</hardwareInterface>
        </joint>
        <actuator name="front_left_str_actr">
            <hardwareInterface>hardware_interface/EffortJointInterface</hardwareInterface>
            <mechanicalReduction>1</mechanicalReduction>
        </actuator>
    </transmission>
    <transmission name="rear_right_str_tran">
        <type>transmission_interface/SimpleTransmission</type>
        <joint name="rear_right_str">
            <hardwareInterface>hardware_interface/EffortJointInterface</hardwareInterface>
        </joint>
        <actuator name="rear_right_str_actr">
            <hardwareInterface>hardware_interface/EffortJointInterface</hardwareInterface>
            <mechanicalReduction>1</mechanicalReduction>
        </actuator>
    </transmission>
    <transmission name="front_right_str_tran">
        <type>transmission_interface/SimpleTransmission</type>
        <joint name="front_right_str">
            <hardwareInterface>hardware_interface/EffortJointInterface</hardwareInterface>
        </joint>
        <actuator name="front_right_str_actr">
            <hardwareInterface>hardware_interface/EffortJointInterface</hardwareInterface>
            <mechanicalReduction>1</mechanicalReduction>
        </actuator>
    </transmission>
    <transmission name="front_left_vel_tran">
        <type>transmission_interface/SimpleTransmission</type>
        <joint name="front_left_vel">
            <hardwareInterface>hardware_interface/EffortJointInterface</hardwareInterface>
        </joint>
        <actuator name="front_left_vel_actr">
            <hardwareInterface>hardware_interface/EffortJointInterface</hardwareInterface>
            <mechanicalReduction>1</mechanicalReduction>
        </actuator>
    </transmission>
    <transmission name="front_right_vel_tran">
        <type>transmission_interface/SimpleTransmission</type>
        <joint name="front_right_vel">
            <hardwareInterface>hardware_interface/EffortJointInterface</hardwareInterface>
        </joint>
        <actuator name="front_right_vel_actr">
            <hardwareInterface>hardware_interface/EffortJointInterface</hardwareInterface>
            <mechanicalReduction>1</mechanicalReduction>
        </actuator>
    </transmission>
    <transmission name="rear_left_vel_tran">
        <type>transmission_interface/SimpleTransmission</type>
        <joint name="rear_left_vel">
            <hardwareInterface>hardware_interface/EffortJointInterface</hardwareInterface>
        </joint>
        <actuator name="rear_left_vel_actr">
            <hardwareInterface>hardware_interface/EffortJointInterface</hardwareInterface>
            <mechanicalReduction>1</mechanicalReduction>
        </actuator>
    </transmission>
    <transmission name="rear_right_vel_tran">
        <type>transmission_interface/SimpleTransmission</type>
        <joint name="rear_right_vel">
            <hardwareInterface>hardware_interface/EffortJointInterface</hardwareInterface>
        </joint>
        <actuator name="rear_right_vel_actr">
            <hardwareInterface>hardware_interface/EffortJointInterface</hardwareInterface>
            <mechanicalReduction>1</mechanicalReduction>
        </actuator>
    </transmission>
    <transmission name="joint1_tran">
        <type>transmission_interface/SimpleTransmission</type>
        <joint name="joint1">
            <hardwareInterface>hardware_interface/EffortJointInterface</hardwareInterface>
        </joint>
        <actuator name="joint1_actr">
            <hardwareInterface>hardware_interface/EffortJointInterface</hardwareInterface>
            <mechanicalReduction>1</mechanicalReduction>
        </actuator>
    </transmission>
    <transmission name="joint2_tran">
        <type>transmission_interface/SimpleTransmission</type>
        <joint name="joint2">
            <hardwareInterface>hardware_interface/EffortJointInterface</hardwareInterface>
        </joint>
        <actuator name="joint2_actr">
            <hardwareInterface>hardware_interface/EffortJointInterface</hardwareInterface>
            <mechanicalReduction>1</mechanicalReduction>
        </actuator>
    </transmission>
    <transmission name="joint3_tran">
        <type>transmission_interface/SimpleTransmission</type>
        <joint name="joint3">
            <hardwareInterface>hardware_interface/EffortJointInterface</hardwareInterface>
        </joint>
        <actuator name="joint3_actr">
            <hardwareInterface>hardware_interface/EffortJointInterface</hardwareInterface>
            <mechanicalReduction>1</mechanicalReduction>
        </actuator>
    </transmission>
    <transmission name="joint4_tran">
        <type>transmission_interface/SimpleTransmission</type>
        <joint name="joint4">
            <hardwareInterface>hardware_interface/EffortJointInterface</hardwareInterface>
        </joint>
        <actuator name="joint4_actr">
            <hardwareInterface>hardware_interface/EffortJointInterface</hardwareInterface>
            <mechanicalReduction>1</mechanicalReduction>
        </actuator>
    </transmission>
    <transmission name="joint5_tran">
        <type>transmission_interface/SimpleTransmission</type>
        <joint name="joint5">
            <hardwareInterface>hardware_interface/EffortJointInterface</hardwareInterface>
        </joint>
        <actuator name="joint5_actr">
            <hardwareInterface>hardware_interface/EffortJointInterface</hardwareInterface>
            <mechanicalReduction>1</mechanicalReduction>
        </actuator>
    </transmission>
    <transmission name="joint6_tran">
        <type>transmission_interface/SimpleTransmission</type>
        <joint name="joint6">
            <hardwareInterface>hardware_interface/EffortJointInterface</hardwareInterface>
        </joint>
        <actuator name="joint6_actr">
            <hardwareInterface>hardware_interface/EffortJointInterface</hardwareInterface>
            <mechanicalReduction>1</mechanicalReduction>
        </actuator>
    </transmission>
    <gazebo>
        <plugin filename="libgazebo_ros_control.so" name="control">
            <robotNamespace>/mmrobot</robotNamespace>
            <robotSimType>gazebo_ros_control/DefaultRobotHWSim</robotSimType>
        </plugin>
        <plugin name="gazebo_ros_control">
            <robotNamespace>/</robotNamespace>
        </plugin>
    </gazebo>
    <gazebo reference="base_link">
        <material>Gazebo/Silver</material>
        <mu1>0.2</mu1>
        <mu2>0.2</mu2>
        <selfCollide>true</selfCollide>
        <gravity>true</gravity>
    </gazebo>
    <gazebo reference="caster_1">
        <material>Gazebo/Blue</material>
        <mu1>0.2</mu1>
        <mu2>0.2</mu2>
        <selfCollide>true</selfCollide>
    </gazebo>
    <gazebo reference="caster_2">
        <material>Gazebo/Blue</material>
        <mu1>0.2</mu1>
        <mu2>0.2</mu2>
        <selfCollide>true</selfCollide>
    </gazebo>
    <gazebo reference="caster_3">
        <material>Gazebo/Blue</material>
        <mu1>0.2</mu1>
        <mu2>0.2</mu2>
        <selfCollide>true</selfCollide>
    </gazebo>
    <gazebo reference="caster_4">
        <material>Gazebo/Blue</material>
        <mu1>0.2</mu1>
        <mu2>0.2</mu2>
        <selfCollide>true</selfCollide>
    </gazebo>
    <gazebo reference="wheel_1">
        <material>Gazebo/Red</material>
        <mu1>0.2</mu1>
        <mu2>0.2</mu2>
        <selfCollide>true</selfCollide>
    </gazebo>
    <gazebo reference="wheel_2">
        <material>Gazebo/Red</material>
        <mu1>0.2</mu1>
        <mu2>0.2</mu2>
        <selfCollide>true</selfCollide>
    </gazebo>
    <gazebo reference="wheel_3">
        <material>Gazebo/Red</material>
        <mu1>0.2</mu1>
        <mu2>0.2</mu2>
        <selfCollide>true</selfCollide>
    </gazebo>
    <gazebo reference="wheel_4">
        <material>Gazebo/Red</material>
        <mu1>0.2</mu1>
        <mu2>0.2</mu2>
        <selfCollide>true</selfCollide>
    </gazebo>
    <gazebo reference="link1_1">
        <material>Gazebo/Orange</material>
        <mu1>0.2</mu1>
        <mu2>0.2</mu2>
        <selfCollide>true</selfCollide>
    </gazebo>
    <gazebo reference="link2_1">
        <material>Gazebo/Black</material>
        <mu1>0.2</mu1>
        <mu2>0.2</mu2>
        <selfCollide>true</selfCollide>
    </gazebo>
    <gazebo reference="link3_1">
        <material>Gazebo/Yellow</material>
        <mu1>0.2</mu1>
        <mu2>0.2</mu2>
        <selfCollide>true</selfCollide>
    </gazebo>
    <gazebo reference="link4_1">
        <material>Gazebo/Blue</material>
        <mu1>0.2</mu1>
        <mu2>0.2</mu2>
        <selfCollide>true</selfCollide>
    </gazebo>
    <gazebo reference="link5_1">
        <material>Gazebo/Green</material>
        <mu1>0.2</mu1>
        <mu2>0.2</mu2>
        <selfCollide>true</selfCollide>
    </gazebo>
    <gazebo reference="gripper_1">
        <material>Gazebo/Red</material>
        <mu1>0.2</mu1>
        <mu2>0.2</mu2>
        <selfCollide>true</selfCollide>
    </gazebo>
    <link name="base_link">
        <inertial>
            <origin rpy="0 0 0" xyz="-0.008302916104735372 0.0019959211199075295 0.10474586187724126" />
            <mass value="4.270686017056189" />
            <inertia ixx="0.13928" ixy="0.0" ixz="-0.0" iyy="0.118374" iyz="0.00154" izz="0.240349" />
        </inertial>
        <visual>
            <origin rpy="0 0 0" xyz="0 0 0" />
            <geometry>
                <mesh filename="package://mmrobot_description/meshes/base_link.stl" scale="0.001 0.001 0.001" />
            </geometry>
            <material name="silver" />
        </visual>
        <collision>
            <origin rpy="0 0 0" xyz="0 0 0" />
            <geometry>
                <mesh filename="package://mmrobot_description/meshes/base_link.stl" scale="0.001 0.001 0.001" />
            </geometry>
        </collision>
    </link>
    <link name="caster_1">
        <inertial>
            <origin rpy="0 0 0" xyz="0.0021887482224724475 -8.803289413272797e-06 -0.03272852540499743" />
            <mass value="0.28102861139928476" />
            <inertia ixx="0.000303" ixy="0.0" ixz="1.3e-05" iyy="0.000386" iyz="-0.0" izz="0.000367" />
        </inertial>
        <visual>
            <origin rpy="0 0 0" xyz="-0.172197 -0.204601 -0.097687" />
            <geometry>
                <mesh filename="package://mmrobot_description/meshes/caster_1.stl" scale="0.001 0.001 0.001" />
            </geometry>
            <material name="silver" />
        </visual>
        <collision>
            <origin rpy="0 0 0" xyz="-0.172197 -0.204601 -0.097687" />
            <geometry>
                <mesh filename="package://mmrobot_description/meshes/caster_1.stl" scale="0.001 0.001 0.001" />
            </geometry>
        </collision>
    </link>
    <link name="caster_2">
        <inertial>
            <origin rpy="0 0 0" xyz="0.0021887482224724752 -8.803289413106263e-06 -0.032728525404997724" />
            <mass value="0.28102861139928476" />
            <inertia ixx="0.000303" ixy="0.0" ixz="1.3e-05" iyy="0.000386" iyz="-0.0" izz="0.000367" />
        </inertial>
        <visual>
            <origin rpy="0 0 0" xyz="-0.172197 0.191399 -0.097687" />
            <geometry>
                <mesh filename="package://mmrobot_description/meshes/caster_2.stl" scale="0.001 0.001 0.001" />
            </geometry>
            <material name="silver" />
        </visual>
        <collision>
            <origin rpy="0 0 0" xyz="-0.172197 0.191399 -0.097687" />
            <geometry>
                <mesh filename="package://mmrobot_description/meshes/caster_2.stl" scale="0.001 0.001 0.001" />
            </geometry>
        </collision>
    </link>
    <link name="caster_3">
        <inertial>
            <origin rpy="0 0 0" xyz="0.0021887482224735577 -8.803289413272797e-06 -0.032728525404997474" />
            <mass value="0.28102861139928476" />
            <inertia ixx="0.000303" ixy="0.0" ixz="1.3e-05" iyy="0.000386" iyz="-0.0" izz="0.000367" />
        </inertial>
        <visual>
            <origin rpy="0 0 0" xyz="0.188803 -0.204601 -0.097687" />
            <geometry>
                <mesh filename="package://mmrobot_description/meshes/caster_3.stl" scale="0.001 0.001 0.001" />
            </geometry>
            <material name="silver" />
        </visual>
        <collision>
            <origin rpy="0 0 0" xyz="0.188803 -0.204601 -0.097687" />
            <geometry>
                <mesh filename="package://mmrobot_description/meshes/caster_3.stl" scale="0.001 0.001 0.001" />
            </geometry>
        </collision>
    </link>
    <link name="caster_4">
        <inertial>
            <origin rpy="0 0 0" xyz="0.0021887482224734744 -8.803289413161774e-06 -0.0327285254049975" />
            <mass value="0.28102861139928476" />
            <inertia ixx="0.000303" ixy="0.0" ixz="1.3e-05" iyy="0.000386" iyz="-0.0" izz="0.000367" />
        </inertial>
        <visual>
            <origin rpy="0 0 0" xyz="0.188803 0.191399 -0.097687" />
            <geometry>
                <mesh filename="package://mmrobot_description/meshes/caster_4.stl" scale="0.001 0.001 0.001" />
            </geometry>
            <material name="silver" />
        </visual>
        <collision>
            <origin rpy="0 0 0" xyz="0.188803 0.191399 -0.097687" />
            <geometry>
                <mesh filename="package://mmrobot_description/meshes/caster_4.stl" scale="0.001 0.001 0.001" />
            </geometry>
        </collision>
    </link>
    <link name="wheel_1">
        <inertial>
            <origin rpy="0 0 0" xyz="0.017500080071390617 -9.961900612753816e-08 -4.7046075932893894e-07" />
            <mass value="0.1516370852065331" />
            <inertia ixx="0.000272" ixy="0.0" ixz="0.0" iyy="0.000151" iyz="-0.0" izz="0.000151" />
        </inertial>
        <visual>
            <origin rpy="0 0 0" xyz="-0.154697 0.191399 -0.050187" />
            <geometry>
                <mesh filename="package://mmrobot_description/meshes/wheel_1.stl" scale="0.001 0.001 0.001" />
            </geometry>
            <material name="silver" />
        </visual>
        <collision>
            <origin rpy="0 0 0" xyz="-0.154697 0.191399 -0.050187" />
            <geometry>
                <mesh filename="package://mmrobot_description/meshes/wheel_1.stl" scale="0.001 0.001 0.001" />
            </geometry>
        </collision>
    </link>
    <link name="wheel_2">
        <inertial>
            <origin rpy="0 0 0" xyz="-0.01749991992860825 -9.961900637733834e-08 -4.704607590166887e-07" />
            <mass value="0.1516370852065331" />
            <inertia ixx="0.000272" ixy="0.0" ixz="-0.0" iyy="0.000151" iyz="-0.0" izz="0.000151" />
        </inertial>
        <visual>
            <origin rpy="0 0 0" xyz="0.171303 0.191399 -0.050187" />
            <geometry>
                <mesh filename="package://mmrobot_description/meshes/wheel_2.stl" scale="0.001 0.001 0.001" />
            </geometry>
            <material name="silver" />
        </visual>
        <collision>
            <origin rpy="0 0 0" xyz="0.171303 0.191399 -0.050187" />
            <geometry>
                <mesh filename="package://mmrobot_description/meshes/wheel_2.stl" scale="0.001 0.001 0.001" />
            </geometry>
        </collision>
    </link>
    <link name="wheel_3">
        <inertial>
            <origin rpy="0 0 0" xyz="-0.017499919928609386 -9.961900623856046e-08 -4.704607590028109e-07" />
            <mass value="0.1516370852065331" />
            <inertia ixx="0.000272" ixy="0.0" ixz="-0.0" iyy="0.000151" iyz="0.0" izz="0.000151" />
        </inertial>
        <visual>
            <origin rpy="0 0 0" xyz="-0.189697 -0.204601 -0.050187" />
            <geometry>
                <mesh filename="package://mmrobot_description/meshes/wheel_3.stl" scale="0.001 0.001 0.001" />
            </geometry>
            <material name="silver" />
        </visual>
        <collision>
            <origin rpy="0 0 0" xyz="-0.189697 -0.204601 -0.050187" />
            <geometry>
                <mesh filename="package://mmrobot_description/meshes/wheel_3.stl" scale="0.001 0.001 0.001" />
            </geometry>
        </collision>
    </link>
    <link name="wheel_4">
        <inertial>
            <origin rpy="0 0 0" xyz="-0.017499919928608082 -9.961900601651585e-08 -4.7046075894729977e-07" />
            <mass value="0.1516370852065331" />
            <inertia ixx="0.000272" ixy="-0.0" ixz="-0.0" iyy="0.000151" iyz="0.0" izz="0.000151" />
        </inertial>
        <visual>
            <origin rpy="0 0 0" xyz="0.171303 -0.204601 -0.050187" />
            <geometry>
                <mesh filename="package://mmrobot_description/meshes/wheel_4.stl" scale="0.001 0.001 0.001" />
            </geometry>
            <material name="silver" />
        </visual>
        <collision>
            <origin rpy="0 0 0" xyz="0.171303 -0.204601 -0.050187" />
            <geometry>
                <mesh filename="package://mmrobot_description/meshes/wheel_4.stl" scale="0.001 0.001 0.001" />
            </geometry>
        </collision>
    </link>
    <link name="link1_1">
        <inertial>
            <origin rpy="0 0 0" xyz="0.007423288821467861 0.00 0.2658398914844642" />
            <mass value="2.71512828709575" />
            <inertia ixx="0.007615" ixy="2.6e-05" ixz="-1e-06" iyy="0.042345" iyz="0.0" izz="0.040801" />
        </inertial>
        <visual>
            <origin rpy="0 0 0" xyz="0.008303 0.108436 -0.013973" />
            <geometry>
                <mesh filename="package://mmrobot_description/meshes/link1_1.stl" scale="0.001 0.001 0.001" />
            </geometry>
            <material name="silver" />
        </visual>
        <collision>
            <origin rpy="0 0 0" xyz="0.008303 0.108436 -0.013973" />
            <geometry>
                <mesh filename="package://mmrobot_description/meshes/link1_1.stl" scale="0.001 0.001 0.001" />
            </geometry>
        </collision>
    </link>
    <link name="link2_1">
        <inertial>
            <origin rpy="0 0 0" xyz="0.060201910056791486 -9.961899327670665e-08 0.14618144723867438" />
            <mass value="0.3158936664806258" />
            <inertia ixx="0.004649" ixy="0.0" ixz="-2.9e-05" iyy="0.005101" iyz="-0.0" izz="0.001085" />
        </inertial>
        <visual>
            <origin rpy="0 0 0" xyz="0.062803 0.108899 -0.293037" />
            <geometry>
                <mesh filename="package://mmrobot_description/meshes/link2_1.stl" scale="0.001 0.001 0.001" />
            </geometry>
            <material name="silver" />
        </visual>
        <collision>
            <origin rpy="0 0 0" xyz="0.062803 0.108899 -0.293037" />
            <geometry>
                <mesh filename="package://mmrobot_description/meshes/link2_1.stl" scale="0.001 0.001 0.001" />
            </geometry>
        </collision>
    </link>
    <link name="link3_1">
        <inertial>
            <origin rpy="0 0 0" xyz="0.049950295693916826 0.022775547959725723 0.06441116766073085" />
            <mass value="0.6000339786282222" />
            <inertia ixx="0.001546" ixy="1e-06" ixz="0.0" iyy="0.001176" iyz="6.8e-05" izz="0.001343" />
        </inertial>
        <visual>
            <origin rpy="0 0 0" xyz="0.058303 0.108899 -0.633037" />
            <geometry>
                <mesh filename="package://mmrobot_description/meshes/link3_1.stl" scale="0.001 0.001 0.001" />
            </geometry>
            <material name="silver" />
        </visual>
        <collision>
            <origin rpy="0 0 0" xyz="0.058303 0.108899 -0.633037" />
            <geometry>
                <mesh filename="package://mmrobot_description/meshes/link3_1.stl" scale="0.001 0.001 0.001" />
            </geometry>
        </collision>
    </link>
    <link name="link4_1">
        <inertial>
            <origin rpy="0 0 0" xyz="9.66979278108071e-08 -0.1315678141313511 -4.7064206110114526e-07" />
            <mass value="0.30663454434170156" />
            <inertia ixx="0.005025" ixy="0.0" ixz="-1e-06" iyy="0.000762" iyz="-0.0" izz="0.005301" />
        </inertial>
        <visual>
            <origin rpy="0 0 0" xyz="0.008303 0.142899 -0.708037" />
            <geometry>
                <mesh filename="package://mmrobot_description/meshes/link4_1.stl" scale="0.001 0.001 0.001" />
            </geometry>
            <material name="silver" />
        </visual>
        <collision>
            <origin rpy="0 0 0" xyz="0.008303 0.142899 -0.708037" />
            <geometry>
                <mesh filename="package://mmrobot_description/meshes/link4_1.stl" scale="0.001 0.001 0.001" />
            </geometry>
        </collision>
    </link>
    <link name="link5_1">
        <inertial>
            <origin rpy="0 0 0" xyz="-0.03754551862399426 0.004760604536082291 0.0019665978572358522" />
            <mass value="0.1685818020240436" />
            <inertia ixx="0.000136" ixy="-0.0" ixz="-0.0" iyy="0.000157" iyz="-1.1e-05" izz="0.000137" />
        </inertial>
        <visual>
            <origin rpy="0 0 0" xyz="-0.029697 0.442899 -0.708037" />
            <geometry>
                <mesh filename="package://mmrobot_description/meshes/link5_1.stl" scale="0.001 0.001 0.001" />
            </geometry>
            <material name="silver" />
        </visual>
        <collision>
            <origin rpy="0 0 0" xyz="-0.029697 0.442899 -0.708037" />
            <geometry>
                <mesh filename="package://mmrobot_description/meshes/link5_1.stl" scale="0.001 0.001 0.001" />
            </geometry>
        </collision>
    </link>
    <link name="gripper_1">
        <inertial>
            <origin rpy="0 0 0" xyz="-1.3848205814502058e-05 -0.03231009447183375 -1.4398737937293404e-05" />
            <mass value="0.11060260658922733" />
            <inertia ixx="7.1e-05" ixy="-0.0" ixz="-0.0" iyy="0.000137" iyz="-0.0" izz="0.000171" />
        </inertial>
        <visual>
            <origin rpy="0 0 0" xyz="0.007803 0.476399 -0.708037" />
            <geometry>
                <mesh filename="package://mmrobot_description/meshes/gripper_1.stl" scale="0.001 0.001 0.001" />
            </geometry>
            <material name="silver" />
        </visual>
        <collision>
            <origin rpy="0 0 0" xyz="0.007803 0.476399 -0.708037" />
            <geometry>
                <mesh filename="package://mmrobot_description/meshes/gripper_1.stl" scale="0.001 0.001 0.001" />
            </geometry>
        </collision>
    </link>
    <joint name="rear_left_str" type="continuous">
        <origin rpy="0 0 0" xyz="0.172197 0.204601 0.097687" />
        <parent link="base_link" />
        <child link="caster_1" />
        <axis xyz="0.0 0.0 -1.0" />
    </joint>
    <joint name="front_left_str" type="continuous">
        <origin rpy="0 0 0" xyz="0.172197 -0.191399 0.097687" />
        <parent link="base_link" />
        <child link="caster_2" />
        <axis xyz="-0.0 -0.0 1.0" />
    </joint>
    <joint name="rear_right_str" type="continuous">
        <origin rpy="0 0 0" xyz="-0.188803 0.204601 0.097687" />
        <parent link="base_link" />
        <child link="caster_3" />
        <axis xyz="0.0 -0.0 1.0" />
    </joint>
    <joint name="front_right_str" type="continuous">
        <origin rpy="0 0 0" xyz="-0.188803 -0.191399 0.097687" />
        <parent link="base_link" />
        <child link="caster_4" />
        <axis xyz="-0.0 0.0 -1.0" />
    </joint>
    <joint name="front_left_vel" type="continuous">
        <origin rpy="0 0 0" xyz="-0.0175 0.0 -0.0475" />
        <parent link="caster_2" />
        <child link="wheel_1" />
        <axis xyz="-1.0 -0.0 -0.0" />
    </joint>
    <joint name="front_right_vel" type="continuous">
        <origin rpy="0 0 0" xyz="0.0175 0.0 -0.0475" />
        <parent link="caster_4" />
        <child link="wheel_2" />
        <axis xyz="1.0 0.0 0.0" />
    </joint>
    <joint name="rear_left_vel" type="continuous">
        <origin rpy="0 0 0" xyz="0.0175 0.0 -0.0475" />
        <parent link="caster_1" />
        <child link="wheel_3" />
        <axis xyz="1.0 0.0 0.0" />
    </joint>
    <joint name="rear_right_vel" type="continuous">
        <origin rpy="0 0 0" xyz="0.0175 0.0 -0.0475" />
        <parent link="caster_3" />
        <child link="wheel_4" />
        <axis xyz="1.0 0.0 0.0" />
    </joint>
    <joint name="joint1" type="continuous">
        <origin rpy="0 0 0" xyz="-0.008303 -0.108436 0.013973" />
        <parent link="base_link" />
        <child link="link1_1" />
        <axis xyz="0.0 0.0 -1.0" />
    </joint>
    <joint name="joint2" type="continuous">
        <origin rpy="0 0 0" xyz="-0.0545 0.0 0.279064" />
        <parent link="link1_1" />
        <child link="link2_1" />
        <axis xyz="1.0 0.0 -0.0" />
    </joint>
    <joint name="joint3" type="continuous">
        <origin rpy="0 0 0" xyz="0.0045 0.0 0.34" />
        <parent link="link2_1" />
        <child link="link3_1" />
        <axis xyz="1.0 0.0 -0.0" />
    </joint>
    <joint name="joint4" type="continuous">
        <origin rpy="0 0 0" xyz="0.05 -0.034 0.075" />
        <parent link="link3_1" />
        <child link="link4_1" />
        <axis xyz="0.0 -1.0 -0.0" />
    </joint>
    <joint name="joint5" type="continuous">
        <origin rpy="0 0 0" xyz="0.038 -0.3 0.0" />
        <parent link="link4_1" />
        <child link="link5_1" />
        <axis xyz="1.0 0.0 -0.0" />
    </joint>
    <joint name="joint6" type="continuous">
        <origin rpy="0 0 0" xyz="-0.0375 -0.0335 0.0" />
        <parent link="link5_1" />
        <child link="gripper_1" />
        <axis xyz="-0.0 1.0 0.0" />
    </joint>
</robot>

